Workbook

Sheet README
A1: JPMorganChase Climate, Nature & Social Risk Analyst Practice Project
A3: Project objective | B3: Primary question | C3: Data basis | D3: Analysis level | E3: Core methods | F3: Primary tools | G3: Current status | H3: Important limitation
A4: Use JPMorganChase public disclosures to identify and prioritize climate, nature and social risk signals that could matter to a bank's traditional risk framework. | B4: Which disclosed sectors and risk drivers deserve deeper monitoring, and why? | C4: JPMorganChase 2024 Sustainability Report, 2024 Climate Report, 2024 Sustainability Data Tables, 2025 Annual Report / Form 10-K, GHG Protocol Category 15 guidance. | D4: Public sector-level / firm-level practice analysis | E4: Risk mapping; exposure screening; carbon-intensity target gap; financed-emissions concentration; data-quality review; risk-control design | F4: Excel first; Python and Power BI later | G4: Phase 1 starter workbook populated with reported data | H4: This is not JPMorganChase internal risk analysis. Public disclosures do not provide counterparty-level exposure, probability of default, loss given default, collateral-level hazard data, or internal model parameters.
A6: The analyst workflow
A7: 1 | B7: Frame the risk question | C7: Start with a banking-risk question, not an ESG metric.
A8: 2 | B8: Establish data lineage | C8: Separate audited financials, sustainability metrics, methodology guidance, and analyst assumptions.
A9: 3 | B9: Map climate drivers to traditional risks | C9: Translate physical and transition drivers into credit/investment, market, operational, and strategic risk channels.
A10: 4 | B10: Screen sector exposure | C10: Use disclosed wholesale credit exposure plus transition/physical vulnerability indicators.
A11: 5 | B11: Assess transition metrics | C11: Compare current portfolio carbon intensity with baseline and 2030 target.
A12: 6 | B12: Assess financed-emissions signals | C12: Examine absolute financed emissions, economic intensity, and PCAF data-quality scores.
A13: 7 | B13: Add nature/social controls | C13: Use screening, due diligence, residual-risk assessment, and escalation logic.
A14: 8 | B14: QA before conclusions | C14: Check boundary, year, unit, overlap, methodology, and data quality.
A15: 9 | B15: Write management insight | C15: State what deserves monitoring, what the evidence supports, and what cannot be concluded from public data.
A17: First assignment
A18: Use the Dashboard and Risk Priority sheets to answer: Which disclosed JPMorganChase sectors show the strongest combination of financial exposure, transition-risk vulnerability, physical-risk vulnerability, carbon-intensity target pressure, and financed-emissions intensity? Then identify the data limitations that prevent you from calling those sectors 'high credit risk.'

Sheet Source Register
A1: Source Register & Data Lineage
A3: Source ID | B3: File / source | C3: Type | D3: Reporting year | E3: Relevant pages / sheet | F3: Primary use | G3: Authority | H3: Loaded? | I3: Analyst note
A4: AR25 | B4: annualreport-2025.pdf | C4: Annual report | D4: 2025 | E4: Financial Highlights p.2; risk/financial sections | F4: Firm financial baseline and scale | G4: Company annual report | H4: Yes | I4: Use audited/official financial figures where available.
A5: 10K25 | B5: corp-10k-2025.pdf | C5: SEC Form 10-K | D5: 2025 | E5: Business; risk factors; MD&A; financial statements | F5: Regulatory financial/risk context | G5: SEC filing | H5: Yes | I5: Primary authoritative source for 2025 financial reporting.
A6: SUS24 | B6: jpmc-sustainability-report-2024.pdf | C6: Sustainability report | D6: 2024 | E6: pp. 22-24; 49-63 | F6: Climate, nature/social risk framework; climate metrics; PCAF metrics | G6: Company report | H6: Yes | I6: All report data generally as of Dec. 31, 2024 unless noted.
A7: CLIM24 | B7: Climate-Report-2024.pdf | C7: Climate report | D7: 2023 | E7: pp. 16-32 | F7: Prior-year climate framework, targets and methodology context | G7: Company report | H7: Yes | I7: Useful for methodology evolution and 2023 comparison.
A8: DATA24 | B8: sustainability-2024-data-tables.xlsx | C8: Structured data tables | D8: 2024 | E8: Carbon Intensity Targets; Absolute Financed & Facilitated; Wholesale Credit Heat Map; ESFR | F8: Primary structured ESG/climate dataset | G8: Company data table | H8: Yes | I8: Preferred for workbook calculations because values are structured.
A9: GHG15 | B9: Chapter15.pdf | C9: GHG Protocol technical guidance | E9: Category 15 Investments | F9: Conceptual accounting guidance for investments | G9: GHG Protocol guidance | H9: Yes | I9: Used for conceptual grounding; JPMorganChase PCAF methodology is the disclosed operational basis for financed-emissions metrics.

Sheet Financial Baseline
A1: Financial Baseline - JPMorganChase Reported Financials
A3: Metric | B3: Unit | C3: 2023 | D3: 2024 | E3: 2025 | F3: Source ID | G3: Source page / note
A4: Total net revenue | B4: $ millions | C4: 158104 | D4: 177556 | E4: 182447 | F4: AR25 | G4: p.2
A5: Total noninterest expense | B5: $ millions | C5: 87172 | D5: 91797 | E5: 95640 | F5: AR25 | G5: p.2
A6: Provision for credit losses | B6: $ millions | C6: 9320 | D6: 10678 | E6: 14212 | F6: AR25 | G6: p.2
A7: Net income | B7: $ millions | C7: 49552 | D7: 58471 | E7: 57048 | F7: AR25 | G7: p.2
A8: Loans | B8: $ millions | C8: 1323706 | D8: 1347988 | E8: 1493429 | F8: AR25 | G8: p.2
A9: Total assets | B9: $ millions | C9: 3875393 | D9: 4002814 | E9: 4424900 | F9: AR25 | G9: p.2
A10: Deposits | B10: $ millions | C10: 2400688 | D10: 2406032 | E10: 2559320 | F10: AR25 | G10: p.2
A11: Common stockholders' equity | B11: $ millions | C11: 300474 | D11: 324708 | E11: 342393 | F11: AR25 | G11: p.2
A12: Total stockholders' equity | B12: $ millions | C12: 327878 | D12: 344758 | E12: 362438 | F12: AR25 | G12: p.2
A13: Market capitalization | B13: $ millions | C13: 489320 | D13: 670618 | E13: 868793 | F13: AR25 | G13: p.2
A14: CET1 capital ratio | B14: % | C14: 0.15 | D14: 0.157 | E14: 0.146 | F14: AR25 | G14: p.2
A15: Return on common equity | B15: % | C15: 0.17 | D15: 0.18 | E15: 0.17 | F15: AR25 | G15: p.2
A17: Derived context
A18: Metric | B18: 2024 | C18: 2025 | D18: Change | E18: Interpretation
A19: Loans | B19: =D8 -> 1347988 | C19: =E8 -> 1493429 | D19: =C19/B19-1 -> 0.10789488 | E19: Loan growth increases the size of exposures that risk management must monitor.
A20: Total assets | B20: =D9 -> 4002814 | C20: =E9 -> 4424900 | D20: =C20/B20-1 -> 0.10544732 | E20: Asset growth provides scale context; climate metrics should not be confused with total balance-sheet exposure.
A21: Net income | B21: =D7 -> 58471 | C21: =E7 -> 57048 | D21: =C21/B21-1 -> -0.024336851 | E21: Earnings are an outcome metric; climate risk analysis asks how risk drivers could affect future earnings/capital/liquidity.
A22: Provision for credit losses | B22: =D6 -> 10678 | C22: =E6 -> 14212 | D22: =C22/B22-1 -> 0.33096085 | E22: Credit-loss provisioning is a traditional credit-risk metric; public climate disclosures do not isolate a climate-attributable portion.

Sheet Climate Risk Framework
A1: Climate Risk Framework - Driver to Traditional Risk
A3: Definitions
A4: Term | B4: JPMorganChase framing
A5: Physical risk | B5: Economic costs and financial losses due to a changing climate. Includes acute, chronic and indirect/second-order drivers.
A6: Transition risk | B6: Financial and economic consequences of society's shift toward a low-carbon economy, including policy, technology and consumer-preference changes.
A8: Risk transmission examples from 2024 Sustainability Report
A9: Traditional risk type | B9: Risk definition / focus | C9: Physical - first order | D9: Physical - second order | E9: Transition - first order | F9: Transition - second order | G9: Analyst translation | H9: Source
A10: Credit & investment | B10: Default/change in credit profile; principal loss or lower expected investment return | C10: Severe weather can damage collateral and interrupt borrower income. | D10: Rising damage can raise insurance cost or reduce availability, pressuring asset values. | E10: Demand shifts away from carbon-intensive products can reduce profitability of slow-to-adapt clients. | F10: Weak local economies dependent on carbon-intensive industries can raise unemployment and default risk. | G10: Translate driver into borrower cash flow, collateral value, insurance availability, PD/LGD direction and concentration. | H10: SUS24 p.51
A11: Market | B11: Changes in rates, FX, equity/commodity prices, credit spreads or volatility affect asset/liability values. | C11: Catastrophe losses could impair an insurer and collapse its equity value. | D11: Insurance availability concerns can pressure home prices, mortgage performance and MBS values. | E11: EV demand can hurt equity value of slow-transition auto manufacturers. | F11: EV supply-chain constraints can raise commodity prices and volatility. | G11: Translate driver into price, spread, volatility, hedging and valuation channels. | H11: SUS24 p.51
A12: Operational | B12: Adverse outcome from failed processes/systems, human factors or external events; includes compliance, legal and model risk. | C12: Flood/cyclone could damage a JPMorganChase facility and disrupt operations. | D12: Migration from repeatedly affected regions could create hiring/retention challenges. | E12: New climate models and regulatory expectations can increase compliance/model risk. | F12: Fast-evolving legal landscape can increase scrutiny, litigation and legal cost. | G12: Translate driver into business continuity, model risk, compliance cost, legal exposure and control requirements. | H12: SUS24 pp.51-52
A13: Strategic | B13: Risk to earnings, capital, liquidity or reputation from poor plans or inadequate response to operating-environment changes. | C13: Property investments may face higher physical damage, repair costs and lower profitability. | D13: Mortgage expansion in areas with insurance retreat can reduce revenues. | E13: Failure to capture green opportunities or retain traditional-energy clients can weaken business performance. | F13: Failure to adapt can weaken status as a leading banking partner. | G13: Translate driver into revenue mix, client retention, product strategy, capital allocation and reputation. | H13: SUS24 p.52
A15: Framework capabilities
A16: Risk Governance | B16: Scenario Analysis | C16: Risk Identification | D16: Risk Measurement | E16: Data Management | F16: Reporting & Disclosures
A17: Escalation and oversight | B17: NGFS/IPCC and internal scenarios | C17: Identify vulnerable sectors, clients and exposures | D17: Quantify impacts within traditional risk types | E17: Build reliable data, taxonomy and controls | F17: Communicate methods, metrics, assumptions and limitations

Sheet Wholesale Credit Heatmap
A1: Wholesale Credit Exposure & Climate Vulnerability Screening - Dec. 31, 2024
A3: Sector | B3: Credit exposure ($mm) | C3: Transition risk | D3: Physical risk | E3: Transition score | F3: Physical score | G3: Combined vulnerability score | H3: Exposure x vulnerability ($mm-score) | I3: Screening status | J3: Source
A4: Commercial & Industrial | B4: 506877 | C4: Moderate | D4: Moderate | E4: =IF(C4="High",3,IF(C4="Moderate",2,IF(C4="Low",1,0))) -> 2 | F4: =IF(D4="Very high",5,IF(D4="High",4,IF(D4="Moderate",3,IF(D4="Low",2,IF(D4="Very Low",1,0))))) -> 3 | G4: =IF(OR(E4=0,F4=0),MAX(E4/3,F4/5),(E4/3+F4/5)/2) -> 0.63333333 | H4: =B4*G4 -> 321022.1 | I4: =IF(G4>=0.8,"Priority 1",IF(G4>=0.6,"Priority 2",IF(G4>=0.4,"Priority 3","Lower"))) -> Priority 2 | J4: DATA24 / Wholesale Credit Heat Map
A5: Consumer & Retail | B5: 129815 | C5: Moderate | D5: Low | E5: =IF(C5="High",3,IF(C5="Moderate",2,IF(C5="Low",1,0))) -> 2 | F5: =IF(D5="Very high",5,IF(D5="High",4,IF(D5="Moderate",3,IF(D5="Low",2,IF(D5="Very Low",1,0))))) -> 2 | G5: =IF(OR(E5=0,F5=0),MAX(E5/3,F5/5),(E5/3+F5/5)/2) -> 0.53333333 | H5: =B5*G5 -> 69234.667 | I5: =IF(G5>=0.8,"Priority 1",IF(G5>=0.6,"Priority 2",IF(G5>=0.4,"Priority 3","Lower"))) -> Priority 3 | J5: DATA24 / Wholesale Credit Heat Map
A6: Food & Beverage | B6: 35457 | C6: Moderate | D6: Low | E6: =IF(C6="High",3,IF(C6="Moderate",2,IF(C6="Low",1,0))) -> 2 | F6: =IF(D6="Very high",5,IF(D6="High",4,IF(D6="Moderate",3,IF(D6="Low",2,IF(D6="Very Low",1,0))))) -> 2 | G6: =IF(OR(E6=0,F6=0),MAX(E6/3,F6/5),(E6/3+F6/5)/2) -> 0.53333333 | H6: =B6*G6 -> 18910.4 | I6: =IF(G6>=0.8,"Priority 1",IF(G6>=0.6,"Priority 2",IF(G6>=0.4,"Priority 3","Lower"))) -> Priority 3 | J6: DATA24 / Wholesale Credit Heat Map
A7: Technology, Media & Telecommunications | B7: 84716 | C7: Moderate | D7: Moderate | E7: =IF(C7="High",3,IF(C7="Moderate",2,IF(C7="Low",1,0))) -> 2 | F7: =IF(D7="Very high",5,IF(D7="High",4,IF(D7="Moderate",3,IF(D7="Low",2,IF(D7="Very Low",1,0))))) -> 3 | G7: =IF(OR(E7=0,F7=0),MAX(E7/3,F7/5),(E7/3+F7/5)/2) -> 0.63333333 | H7: =B7*G7 -> 53653.467 | I7: =IF(G7>=0.8,"Priority 1",IF(G7>=0.6,"Priority 2",IF(G7>=0.4,"Priority 3","Lower"))) -> Priority 2 | J7: DATA24 / Wholesale Credit Heat Map
A8: Industrials | B8: 72530 | C8: Moderate | D8: Moderate | E8: =IF(C8="High",3,IF(C8="Moderate",2,IF(C8="Low",1,0))) -> 2 | F8: =IF(D8="Very high",5,IF(D8="High",4,IF(D8="Moderate",3,IF(D8="Low",2,IF(D8="Very Low",1,0))))) -> 3 | G8: =IF(OR(E8=0,F8=0),MAX(E8/3,F8/5),(E8/3+F8/5)/2) -> 0.63333333 | H8: =B8*G8 -> 45935.667 | I8: =IF(G8>=0.8,"Priority 1",IF(G8>=0.6,"Priority 2",IF(G8>=0.4,"Priority 3","Lower"))) -> Priority 2 | J8: DATA24 / Wholesale Credit Heat Map
A9: Agriculture, Forest Products & Textiles | B9: 13855 | C9: Moderate | D9: High | E9: =IF(C9="High",3,IF(C9="Moderate",2,IF(C9="Low",1,0))) -> 2 | F9: =IF(D9="Very high",5,IF(D9="High",4,IF(D9="Moderate",3,IF(D9="Low",2,IF(D9="Very Low",1,0))))) -> 4 | G9: =IF(OR(E9=0,F9=0),MAX(E9/3,F9/5),(E9/3+F9/5)/2) -> 0.73333333 | H9: =B9*G9 -> 10160.333 | I9: =IF(G9>=0.8,"Priority 1",IF(G9>=0.6,"Priority 2",IF(G9>=0.4,"Priority 3","Lower"))) -> Priority 2 | J9: DATA24 / Wholesale Credit Heat Map
A10: Aerospace & Defense | B10: 8489 | C10: High | D10: Moderate | E10: =IF(C10="High",3,IF(C10="Moderate",2,IF(C10="Low",1,0))) -> 3 | F10: =IF(D10="Very high",5,IF(D10="High",4,IF(D10="Moderate",3,IF(D10="Low",2,IF(D10="Very Low",1,0))))) -> 3 | G10: =IF(OR(E10=0,F10=0),MAX(E10/3,F10/5),(E10/3+F10/5)/2) -> 0.8 | H10: =B10*G10 -> 6791.2 | I10: =IF(G10>=0.8,"Priority 1",IF(G10>=0.6,"Priority 2",IF(G10>=0.4,"Priority 3","Lower"))) -> Priority 1 | J10: DATA24 / Wholesale Credit Heat Map
A11: Healthcare | B11: 64224 | C11: Low | D11: Moderate | E11: =IF(C11="High",3,IF(C11="Moderate",2,IF(C11="Low",1,0))) -> 1 | F11: =IF(D11="Very high",5,IF(D11="High",4,IF(D11="Moderate",3,IF(D11="Low",2,IF(D11="Very Low",1,0))))) -> 3 | G11: =IF(OR(E11=0,F11=0),MAX(E11/3,F11/5),(E11/3+F11/5)/2) -> 0.46666667 | H11: =B11*G11 -> 29971.2 | I11: =IF(G11>=0.8,"Priority 1",IF(G11>=0.6,"Priority 2",IF(G11>=0.4,"Priority 3","Lower"))) -> Priority 3 | J11: DATA24 / Wholesale Credit Heat Map
A12: Oil & Gas | B12: 31724 | C12: High | D12: High | E12: =IF(C12="High",3,IF(C12="Moderate",2,IF(C12="Low",1,0))) -> 3 | F12: =IF(D12="Very high",5,IF(D12="High",4,IF(D12="Moderate",3,IF(D12="Low",2,IF(D12="Very Low",1,0))))) -> 4 | G12: =IF(OR(E12=0,F12=0),MAX(E12/3,F12/5),(E12/3+F12/5)/2) -> 0.9 | H12: =B12*G12 -> 28551.6 | I12: =IF(G12>=0.8,"Priority 1",IF(G12>=0.6,"Priority 2",IF(G12>=0.4,"Priority 3","Lower"))) -> Priority 1 | J12: DATA24 / Wholesale Credit Heat Map
A13: Auto Manufacturing | B13: 16865 | C13: High | D13: Moderate | E13: =IF(C13="High",3,IF(C13="Moderate",2,IF(C13="Low",1,0))) -> 3 | F13: =IF(D13="Very high",5,IF(D13="High",4,IF(D13="Moderate",3,IF(D13="Low",2,IF(D13="Very Low",1,0))))) -> 3 | G13: =IF(OR(E13=0,F13=0),MAX(E13/3,F13/5),(E13/3+F13/5)/2) -> 0.8 | H13: =B13*G13 -> 13492 | I13: =IF(G13>=0.8,"Priority 1",IF(G13>=0.6,"Priority 2",IF(G13>=0.4,"Priority 3","Lower"))) -> Priority 1 | J13: DATA24 / Wholesale Credit Heat Map
A14: Electric | B14: 12909 | C14: Moderate | D14: Very high | E14: =IF(C14="High",3,IF(C14="Moderate",2,IF(C14="Low",1,0))) -> 2 | F14: =IF(D14="Very high",5,IF(D14="High",4,IF(D14="Moderate",3,IF(D14="Low",2,IF(D14="Very Low",1,0))))) -> 5 | G14: =IF(OR(E14=0,F14=0),MAX(E14/3,F14/5),(E14/3+F14/5)/2) -> 0.83333333 | H14: =B14*G14 -> 10757.5 | I14: =IF(G14>=0.8,"Priority 1",IF(G14>=0.6,"Priority 2",IF(G14>=0.4,"Priority 3","Lower"))) -> Priority 1 | J14: DATA24 / Wholesale Credit Heat Map
A15: Gas | B15: 9439 | C15: High | D15: High | E15: =IF(C15="High",3,IF(C15="Moderate",2,IF(C15="Low",1,0))) -> 3 | F15: =IF(D15="Very high",5,IF(D15="High",4,IF(D15="Moderate",3,IF(D15="Low",2,IF(D15="Very Low",1,0))))) -> 4 | G15: =IF(OR(E15=0,F15=0),MAX(E15/3,F15/5),(E15/3+F15/5)/2) -> 0.9 | H15: =B15*G15 -> 8495.1 | I15: =IF(G15>=0.8,"Priority 1",IF(G15>=0.6,"Priority 2",IF(G15>=0.4,"Priority 3","Lower"))) -> Priority 1 | J15: DATA24 / Wholesale Credit Heat Map
... A22: Real Estate | B22: 207050 | C22: Moderate | D22: Low | E22: =IF(C22="High",3,IF(C22="Moderate",2,IF(C22="Low",1,0))) -> 2 | F22: =IF(D22="Very high",5,IF(D22="High",4,IF(D22="Moderate",3,IF(D22="Low",2,IF(D22="Very Low",1,0))))) -> 2 | G22: =IF(OR(E22=0,F22=0),MAX(E22/3,F22/5),(E22/3+F22/5)/2) -> 0.53333333 | H22: =B22*G22 -> 110426.67 | I22: =IF(G22>=0.8,"Priority 1",IF(G22>=0.6,"Priority 2",IF(G22>=0.4,"Priority 3","Lower"))) -> Priority 3 | J22: DATA24 / Wholesale Credit Heat Map
A24: Important: The exposure values above are public sector/subsector disclosures. Some rows can overlap hierarchically in the source heat map, so do not sum them blindly. JPMorganChase states the heat-map categories reflect sector-level vulnerability and should not be interpreted as a direct assessment of the Firm's own portfolio vulnerability or any individual counterparty.

Sheet Carbon Intensity Targets
A1: Portfolio Carbon Intensity Targets - Progress as of Dec. 31, 2024
A3: Sector | B3: Scopes included | C3: Unit | D3: Baseline year | E3: Baseline intensity | F3: 2030 target intensity / change | G3: 2024 intensity | H3: Change from baseline | I3: Required total reduction | J3: Progress achieved | K3: Remaining gap to target | L3: Source
A4: Energy Mix | B4: Scope 3 (end use) | C4: gCO2/MJ | D4: 2019 | E4: 45.9 | F4: 29.5 | G4: 30.6 | H4: -0.332 | I4: -0.36 | J4: =IF(I4=0,0,H4/I4) -> 0.92222222 | K4: =ABS(I4)-MAX(0,-H4) -> 0.028 | L4: DATA24 / Carbon Intensity Targets
A5: Oil & Gas Operational | B5: Scopes 1 and 2 | C5: gCO2e/MJ | D5: 2019 | E5: 4.9 | G5: 4 | H5: -0.172 | I5: -0.45 | J5: =IF(I5=0,0,H5/I5) -> 0.38222222 | K5: =ABS(I5)-MAX(0,-H5) -> 0.278 | L5: DATA24 / Carbon Intensity Targets
A6: Electric Power | B6: Scope 1 | C6: kgCO2/MWh | D6: 2019 | E6: 342.6 | F6: 105.3 | G6: 248.4 | H6: -0.275 | I6: -0.69 | J6: =IF(I6=0,0,H6/I6) -> 0.39855072 | K6: =ABS(I6)-MAX(0,-H6) -> 0.415 | L6: DATA24 / Carbon Intensity Targets
A7: Auto Manufacturing | B7: Scopes 1, 2 and 3 (tank-to-wheel) | C7: gCO2e/km | D7: 2019 | E7: 164.8 | F7: 86.1 | G7: 131.3 | H7: -0.203 | I7: -0.48 | J7: =IF(I7=0,0,H7/I7) -> 0.42291667 | K7: =ABS(I7)-MAX(0,-H7) -> 0.277 | L7: DATA24 / Carbon Intensity Targets
A8: Aviation | B8: Scope 1 (tank-to-wake) | C8: gCO2/RTK | D8: 2021 | E8: 972.6 | F8: 625 | G8: 777.3 | H8: -0.201 | I8: -0.36 | J8: =IF(I8=0,0,H8/I8) -> 0.55833333 | K8: =ABS(I8)-MAX(0,-H8) -> 0.159 | L8: DATA24 / Carbon Intensity Targets
A9: Shipping | B9: Scope 1 (tank-to-wake) | C9: gCO2/t-nm | D9: 2021 | E9: 10.9 | F9: 8.4 | G9: 11.5 | H9: 0.057 | I9: -0.23 | J9: =IF(I9=0,0,H9/I9) -> -0.24782609 | K9: =ABS(I9)-MAX(0,-H9) -> 0.23 | L9: DATA24 / Carbon Intensity Targets
A10: Iron & Steel | B10: Scopes 1 and 2 | C10: tCO2e/t crude steel | D10: 2020 | E10: 1.4 | F10: 0.981 | G10: 1.291 | H10: -0.086 | I10: -0.3 | J10: =IF(I10=0,0,H10/I10) -> 0.28666667 | K10: =ABS(I10)-MAX(0,-H10) -> 0.214 | L10: DATA24 / Carbon Intensity Targets
A11: Cement | B11: Scopes 1 and 2 | C11: kgCO2e/t cementitious product | D11: 2020 | E11: 639.3 | F11: 460 | G11: 619.6 | H11: -0.031 | I11: -0.28 | J11: =IF(I11=0,0,H11/I11) -> 0.11071429 | K11: =ABS(I11)-MAX(0,-H11) -> 0.249 | L11: DATA24 / Carbon Intensity Targets
A12: Aluminum | B12: Scopes 1 and 2 | C12: tCO2e/t aluminum | D12: 2021 | E12: 8.6 | F12: 6.5 | G12: 9.5 | H12: 0.104 | I12: -0.24 | J12: =IF(I12=0,0,H12/I12) -> -0.43333333 | K12: =ABS(I12)-MAX(0,-H12) -> 0.24 | L12: DATA24 / Carbon Intensity Targets
A14: Analyst flags
A15: Flag | B15: Condition | C15: Interpretation | D15: Action
A16: Moving away from baseline | B16: Change from baseline > 0 | C16: Portfolio intensity increased rather than declined. | D16: Investigate exposure mix, client intensity and methodology changes.
A17: Low progress | B17: Progress achieved < 50% | C17: Less than half of required reduction has been achieved. | D17: Assess trajectory, client transition plans and external prerequisites.
A18: Boundary mismatch | B18: Scopes differ by sector | C18: Carbon intensities are not directly comparable across sectors. | D18: Do not rank sectors by raw intensity values across different units/boundaries.
A19: Methodology change | B19: Revised baselines / data updates | C19: Trend can move because of data-quality or methodology changes. | D19: Preserve version history and document restatements.

Sheet Financed Emissions
A1: PCAF-Aligned Absolute Financed Emissions - Reported 2024
A3: Sector | B3: Scopes included | C3: Committed lending financed emissions (MtCO2e) | D3: Capital markets facilitated emissions (MtCO2e) | E3: Committed lending economic intensity (tCO2e/$1mm) | F3: Capital markets economic intensity (tCO2e/$1mm) | G3: Data quality score | H3: Outstanding lending financed emissions (MtCO2e) | I3: Outstanding lending economic intensity (tCO2e/$1mm) | J3: Analyst flag | K3: Source
A4: Energy Mix | B4: Scope 3 (end use) | C4: 84.4 | D4: 42.9 | E4: 1876.2 | F4: 2961.8 | G4: 3.1 | H4: 19.3 | I4: 3709.2 | J4: =IF(G4>3,"Data quality review",IF(E4>1000,"High emissions intensity","Monitor")) -> Data quality review | K4: DATA24 / Absolute Financed & Facilitated
A5: Oil and Gas Operational | B5: Scopes 1 and 2 | C5: 4.3 | D5: 2.9 | E5: 212.2 | F5: 404.1 | G5: 3.2 | H5: 0.8 | I5: 242.5 | J5: =IF(G5>3,"Data quality review",IF(E5>1000,"High emissions intensity","Monitor")) -> Data quality review | K5: DATA24 / Absolute Financed & Facilitated
A6: Electric Power | B6: Scope 1 | C6: 21.1 | D6: 6.3 | E6: 515.3 | F6: 438.8 | G6: 3.1 | H6: 1.9 | I6: 621.8 | J6: =IF(G6>3,"Data quality review",IF(E6>1000,"High emissions intensity","Monitor")) -> Data quality review | K6: DATA24 / Absolute Financed & Facilitated
A7: Auto Manufacturing | B7: Scopes 1, 2 and 3 (tank-to-wheel) | C7: 2.2 | D7: 1 | E7: 511.6 | F7: 457 | G7: 3.1 | H7: 0.2 | I7: 853 | J7: =IF(G7>3,"Data quality review",IF(E7>1000,"High emissions intensity","Monitor")) -> Data quality review | K7: DATA24 / Absolute Financed & Facilitated
A8: Aviation | B8: Scope 1 (tank-to-wake) | C8: 1.2 | D8: 0.6 | E8: 762.3 | F8: 766.6 | G8: 3 | H8: 0.1 | I8: 601.5 | J8: =IF(G8>3,"Data quality review",IF(E8>1000,"High emissions intensity","Monitor")) -> Monitor | K8: DATA24 / Absolute Financed & Facilitated
A9: Shipping | B9: Scope 1 (tank-to-wake) | C9: 0.2 | D9: 0.1 | E9: 395.5 | F9: 306.4 | G9: 2.6 | H9: 0.04 | I9: 251.1 | J9: =IF(G9>3,"Data quality review",IF(E9>1000,"High emissions intensity","Monitor")) -> Monitor | K9: DATA24 / Absolute Financed & Facilitated
A10: Iron & Steel | B10: Scopes 1 and 2 | C10: 3.4 | D10: 1 | E10: 1592.6 | F10: 1504.3 | G10: 1.2 | H10: 0.6 | I10: 1444.6 | J10: =IF(G10>3,"Data quality review",IF(E10>1000,"High emissions intensity","Monitor")) -> High emissions intensity | K10: DATA24 / Absolute Financed & Facilitated
A11: Cement | B11: Scopes 1 and 2 | C11: 1.4 | D11: 0.3 | E11: 1310.5 | F11: 1113.3 | G11: 1.4 | H11: 0.5 | I11: 1954.1 | J11: =IF(G11>3,"Data quality review",IF(E11>1000,"High emissions intensity","Monitor")) -> High emissions intensity | K11: DATA24 / Absolute Financed & Facilitated
A12: Aluminum | B12: Scopes 1 and 2 | C12: 0.4 | D12: 0.6 | E12: 706 | F12: 1804.1 | G12: 3 | H12: 0.1 | I12: 970.2 | J12: =IF(G12>3,"Data quality review",IF(E12>1000,"High emissions intensity","Monitor")) -> Monitor | K12: DATA24 / Absolute Financed & Facilitated
A14: Methodology notes you must remember
A15: Outstanding exposure | B15: PCAF-aligned table defines financed emissions using outstanding exposure / company value x company emissions. Outstanding exposure is the loan amount drawn as of year-end.
A16: Company value | B16: EVIC is used; if unavailable, JPMorganChase uses total company equity + debt, with negative equity treated as zero.
A17: Facilitated emissions | B17: Capital-markets facilitated emissions use transaction attribution and a 33% weighting factor in the PCAF-aligned table.
A18: Economic intensity | B18: Absolute emissions per $1 million loaned or facilitated.
A19: Data quality | B19: 1 = highest quality; 5 = lowest. Sector value is financing-weighted.
A20: Do not equate emissions with risk | B20: High financed emissions can be a transition-risk indicator, but they do not directly measure probability of default or expected loss.

Sheet Nature Social Risk
A1: Nature & Social Risk - Screening, Assessment and Escalation
A3: Stage | B3: Purpose | C3: What is reviewed | D3: Example N&S topics | E3: Risk question | F3: Possible outcome | G3: Analyst evidence | H3: Source
A4: 1. Screening | B4: Identify potentially material N&S risks | C4: Relevant clients and transactions using N&S Risk Taxonomy and activity/location criteria | D4: Biodiversity; air; soil; water; labor and working conditions; health & safety; security; Indigenous Peoples; human rights | E4: Is this client/transaction associated with elevated N&S risk? | F4: Proceed / require deeper review | G4: Sector/activity/location; transaction purpose; client profile | H4: SUS24 p.57
A5: 2. Assessment | B5: Understand severity and mitigation | C5: Severity, client capability, policies, governance, risk management, stakeholder engagement and residual risk | D5: Same topics, evaluated at client/transaction level | E5: How severe is the risk, how well is it managed, and what residual risk remains? | F5: Risk mitigation conditions / support / decline / escalate | G5: Policies; incidents; management systems; controversy history; stakeholder evidence | H5: SUS24 p.57
A6: 3. Escalation & challenge | B6: Independent review of higher-risk cases | C6: LOB assessment challenged by dedicated Risk Management function | D6: Higher-risk clients and transactions | E6: Is residual risk within risk appetite and commercial interests? | F6: Case-by-case decision | G6: Escalation memo; challenge record; decision rationale | H6: SUS24 p.57
A8: Practice case template - fill this in after climate screening
A9: Case ID | B9: Sector / client proxy | C9: N&S driver | D9: Severity (1-5) | E9: Client management quality (1-5) | F9: Residual risk score | G9: Escalate? | H9: Your rationale
F10: =IF(OR(D10="",E10=""),"",D10*(6-E10)) | G10: =IF(F10="","",IF(F10>=12,"Yes","No"))
F11: =IF(OR(D11="",E11=""),"",D11*(6-E11)) | G11: =IF(F11="","",IF(F11>=12,"Yes","No"))
F12: =IF(OR(D12="",E12=""),"",D12*(6-E12)) | G12: =IF(F12="","",IF(F12>=12,"Yes","No"))
F13: =IF(OR(D13="",E13=""),"",D13*(6-E13)) | G13: =IF(F13="","",IF(F13>=12,"Yes","No"))
F14: =IF(OR(D14="",E14=""),"",D14*(6-E14)) | G14: =IF(F14="","",IF(F14>=12,"Yes","No"))
F15: =IF(OR(D15="",E15=""),"",D15*(6-E15)) | G15: =IF(F15="","",IF(F15>=12,"Yes","No"))

Sheet Risk Priority
A1: Integrated Sector Risk Priority - Practice Screening
A3: Sector | B3: Credit exposure ($mm) | C3: Transition risk | D3: Physical risk | E3: Vulnerability score | F3: 2024 carbon-intensity change | G3: Progress toward 2030 target | H3: Outstanding financed-emissions intensity | I3: PCAF data quality | J3: Exposure score | K3: Transition metric score | L3: Emissions score | M3: Composite screening score | N3: Interpretation
A4: Oil & Gas | B4: 31724 | C4: High | D4: High | E4: =((IF(C4="High",3,IF(C4="Moderate",2,IF(C4="Low",1,0)))/3)+(IF(D4="Very high",5,IF(D4="High",4,IF(D4="Moderate",3,IF(D4="Low",2,0))))/5))/2 -> 0.9 | F4: ='Carbon Intensity Targets'!H5 -> -0.172 | G4: ='Carbon Intensity Targets'!J5 -> 0.38222222 | H4: ='Financed Emissions'!I5 -> 242.5 | I4: ='Financed Emissions'!G5 -> 3.2 | J4: =MIN(1,B4/50000) -> 0.63448 | K4: =MAX(0,1-G4) -> 0.61777778 | L4: =MIN(1,H4/2000) -> 0.12125 | M4: =0.35*E4+0.25*J4+0.2*K4+0.2*L4 -> 0.62142556 | N4: =IF(M4>=0.75,"Priority 1 - deep dive",IF(M4>=0.55,"Priority 2 - monitor","Priority 3 - watch")) -> Priority 2 - monitor
A5: Electric Power | B5: 12909 | C5: Moderate | D5: Very high | E5: =((IF(C5="High",3,IF(C5="Moderate",2,IF(C5="Low",1,0)))/3)+(IF(D5="Very high",5,IF(D5="High",4,IF(D5="Moderate",3,IF(D5="Low",2,0))))/5))/2 -> 0.83333333 | F5: ='Carbon Intensity Targets'!H6 -> -0.275 | G5: ='Carbon Intensity Targets'!J6 -> 0.39855072 | H5: ='Financed Emissions'!I6 -> 621.8 | I5: ='Financed Emissions'!G6 -> 3.1 | J5: =MIN(1,B5/50000) -> 0.25818 | K5: =MAX(0,1-G5) -> 0.60144928 | L5: =MIN(1,H5/2000) -> 0.3109 | M5: =0.35*E5+0.25*J5+0.2*K5+0.2*L5 -> 0.53868152 | N5: =IF(M5>=0.75,"Priority 1 - deep dive",IF(M5>=0.55,"Priority 2 - monitor","Priority 3 - watch")) -> Priority 3 - watch
A6: Auto Manufacturing | B6: 16865 | C6: High | D6: Moderate | E6: =((IF(C6="High",3,IF(C6="Moderate",2,IF(C6="Low",1,0)))/3)+(IF(D6="Very high",5,IF(D6="High",4,IF(D6="Moderate",3,IF(D6="Low",2,0))))/5))/2 -> 0.8 | F6: ='Carbon Intensity Targets'!H7 -> -0.203 | G6: ='Carbon Intensity Targets'!J7 -> 0.42291667 | H6: ='Financed Emissions'!I7 -> 853 | I6: ='Financed Emissions'!G7 -> 3.1 | J6: =MIN(1,B6/50000) -> 0.3373 | K6: =MAX(0,1-G6) -> 0.57708333 | L6: =MIN(1,H6/2000) -> 0.4265 | M6: =0.35*E6+0.25*J6+0.2*K6+0.2*L6 -> 0.56504167 | N6: =IF(M6>=0.75,"Priority 1 - deep dive",IF(M6>=0.55,"Priority 2 - monitor","Priority 3 - watch")) -> Priority 2 - monitor
A7: Iron & Steel | B7: 3947 | C7: High | D7: High | E7: =((IF(C7="High",3,IF(C7="Moderate",2,IF(C7="Low",1,0)))/3)+(IF(D7="Very high",5,IF(D7="High",4,IF(D7="Moderate",3,IF(D7="Low",2,0))))/5))/2 -> 0.9 | F7: ='Carbon Intensity Targets'!H10 -> -0.086 | G7: ='Carbon Intensity Targets'!J10 -> 0.28666667 | H7: ='Financed Emissions'!I10 -> 1444.6 | I7: ='Financed Emissions'!G10 -> 1.2 | J7: =MIN(1,B7/50000) -> 0.07894 | K7: =MAX(0,1-G7) -> 0.71333333 | L7: =MIN(1,H7/2000) -> 0.7223 | M7: =0.35*E7+0.25*J7+0.2*K7+0.2*L7 -> 0.62186167 | N7: =IF(M7>=0.75,"Priority 1 - deep dive",IF(M7>=0.55,"Priority 2 - monitor","Priority 3 - watch")) -> Priority 2 - monitor
A8: Aluminum | B8: 1066 | C8: High | D8: Very high | E8: =((IF(C8="High",3,IF(C8="Moderate",2,IF(C8="Low",1,0)))/3)+(IF(D8="Very high",5,IF(D8="High",4,IF(D8="Moderate",3,IF(D8="Low",2,0))))/5))/2 -> 1 | F8: ='Carbon Intensity Targets'!H12 -> 0.104 | G8: ='Carbon Intensity Targets'!J12 -> -0.43333333 | H8: ='Financed Emissions'!I12 -> 970.2 | I8: ='Financed Emissions'!G12 -> 3 | J8: =MIN(1,B8/50000) -> 0.02132 | K8: =MAX(0,1-G8) -> 1.4333333 | L8: =MIN(1,H8/2000) -> 0.4851 | M8: =0.35*E8+0.25*J8+0.2*K8+0.2*L8 -> 0.73901667 | N8: =IF(M8>=0.75,"Priority 1 - deep dive",IF(M8>=0.55,"Priority 2 - monitor","Priority 3 - watch")) -> Priority 2 - monitor
A10: This composite score is an analyst training construct, not a JPMorganChase risk rating. It combines public sector exposure and climate metrics using transparent weights solely to prioritize where to investigate next. It must not be interpreted as probability of default, expected loss, regulatory capital, or JPMorganChase's internal risk appetite.

Sheet QA Controls
A1: QA / Control Matrix
A3: Control ID | B3: Risk | C3: Control objective | D3: Test | E3: Expected result | F3: Current result | G3: Status | H3: Owner | I3: Evidence | J3: Exception | K3: Remediation
A4: C01 | B4: Wrong reporting year | C4: Keep financial and climate dates explicit | D4: Compare source year/date for each dataset | E4: Dates documented; no silent mixing | F4: Financial baseline 2025 vs climate metrics 2024 disclosed separately | G4: Pass | I4: Source Register
A5: C02 | B5: Sector overlap / double counting | C5: Avoid summing parent and child heat-map rows | D5: Review sector hierarchy before aggregation | E5: No unsupported portfolio total | F5: Workbook warns against blind summation | G5: Pass | I5: Wholesale Credit Heatmap
A6: C03 | B6: Scope / unit mismatch | C6: Do not compare raw intensities across incompatible sectors | D6: Check scope and unit before cross-sector ranking | E6: Boundary/units retained with each row | F6: Scope and unit columns populated | G6: Pass | I6: Carbon Intensity Targets
A7: C04 | B7: Financed emissions mistaken for risk | C7: Separate emissions attribution from credit risk | D7: Check conclusions for PD/LGD claims | E7: No credit-risk claim without borrower-level evidence | F7: Explicit limitation included | G7: Pass | I7: README / Financed Emissions
A8: C05 | B8: Low-quality emissions data | C8: Surface PCAF quality score | D8: Flag sectors with score >3 | E8: Review or caveat low-quality data | F8: Formula flag included | G8: Pass | I8: Financed Emissions
A9: C06 | B9: Methodology change | C9: Preserve revised baselines / definitions | D9: Compare current and prior methodology notes | E9: Restatements documented | F9: Shipping revision noted in source data | G9: Review | I9: Carbon Intensity Targets
A10: C07 | B10: Unsupported N&S conclusion | C10: Require evidence and challenge | D10: Check screening/assessment/escalation documentation | E10: Higher-risk cases have rationale | F10: Practice template ready | G10: Not started | I10: Nature Social Risk

Sheet Analyst Questions
A1: Analyst Questions - Work Through in Order
A3: # | B3: Question | C3: Why it matters | D3: Sheet(s) to use | E3: Your answer | F3: Evidence | G3: Confidence | H3: Manager challenge
A4: 1 | B4: What is the bank's financial scale, and which balance-sheet metric is most relevant to a lending-risk discussion? | C4: Establishes financial context before climate interpretation. | D4: Financial Baseline
A5: 2 | B5: How does JPMorganChase define physical and transition climate risk? | C5: Tests whether you understand the bank's own risk language. | D5: Climate Risk Framework
A6: 3 | B6: How can climate drivers transmit into credit/investment, market, operational and strategic risk? | C6: This is core to the role. | D6: Climate Risk Framework
A7: 4 | B7: Which disclosed sectors have the strongest combination of transition and physical vulnerability? | C7: Identifies where deeper work should start. | D7: Wholesale Credit Heatmap
A8: 5 | B8: Which target sectors are moving away from their baselines or showing weak progress? | C8: Finds transition-pathway pressure. | D8: Carbon Intensity Targets
A9: 6 | B9: Which sectors have the highest financed-emissions economic intensity, and what does that indicate? | C9: Connects PCAF metrics to transition-risk screening without overstating them. | D9: Financed Emissions
A10: 7 | B10: How does PCAF data quality alter your confidence in the emissions signal? | C10: Avoids false precision. | D10: Financed Emissions
A11: 8 | B11: Which sector would you prioritize for a deep dive when combining exposure, vulnerability and transition metrics? | C11: Forces prioritization, not description. | D11: Risk Priority
A12: 9 | B12: What additional counterparty-level data would you request before estimating credit loss? | C12: Shows you know what public data cannot answer. | D12: README / Risk Priority
A13: 10 | B13: How would you screen, assess and escalate a nature or social risk in the same sector? | C13: Broadens from climate into the full CN&S role. | D13: Nature Social Risk

Sheet Dashboard
A1: JPMorganChase CN&S Risk Practice Dashboard
A3: 2025 Total Assets ($mm) | E3: 2025 Loans ($mm) | I3: 2024 ESFR
A4: ='Financial Baseline'!E9 -> 4424900 | E4: ='Financial Baseline'!E8 -> 1493429 | I4: 1.13x
A7: Integrated screening - sectors for deeper analysis | H7: What the dashboard does NOT prove
A8: Sector | B8: Composite score | C8: Interpretation | D8: Credit exposure ($mm) | E8: 2024 intensity change | F8: Outstanding FE intensity | H8: 1 | I8: No counterparty PD / LGD
A9: ='Risk Priority'!A4 -> Oil & Gas | B9: ='Risk Priority'!M4 -> 0.62142556 | C9: ='Risk Priority'!N4 -> Priority 2 - monitor | D9: ='Risk Priority'!B4 -> 31724 | E9: ='Risk Priority'!F4 -> -0.172 | F9: ='Risk Priority'!H4 -> 242.5 | H9: 2 | I9: No collateral-level physical hazard
A10: ='Risk Priority'!A5 -> Electric Power | B10: ='Risk Priority'!M5 -> 0.53868152 | C10: ='Risk Priority'!N5 -> Priority 3 - watch | D10: ='Risk Priority'!B5 -> 12909 | E10: ='Risk Priority'!F5 -> -0.275 | F10: ='Risk Priority'!H5 -> 621.8 | H10: 3 | I10: No borrower financial stress model
A11: ='Risk Priority'!A6 -> Auto Manufacturing | B11: ='Risk Priority'!M6 -> 0.56504167 | C11: ='Risk Priority'!N6 -> Priority 2 - monitor | D11: ='Risk Priority'!B6 -> 16865 | E11: ='Risk Priority'!F6 -> -0.203 | F11: ='Risk Priority'!H6 -> 853 | H11: 4 | I11: Sector heat map is vulnerability screening, not direct portfolio risk rating
A12: ='Risk Priority'!A7 -> Iron & Steel | B12: ='Risk Priority'!M7 -> 0.62186167 | C12: ='Risk Priority'!N7 -> Priority 2 - monitor | D12: ='Risk Priority'!B7 -> 3947 | E12: ='Risk Priority'!F7 -> -0.086 | F12: ='Risk Priority'!H7 -> 1444.6 | H12: 5 | I12: Financed emissions are attribution metrics, not expected-loss metrics
A13: ='Risk Priority'!A8 -> Aluminum | B13: ='Risk Priority'!M8 -> 0.73901667 | C13: ='Risk Priority'!N8 -> Priority 2 - monitor | D13: ='Risk Priority'!B8 -> 1066 | E13: ='Risk Priority'!F8 -> 0.104 | F13: ='Risk Priority'!H8 -> 970.2
H15: Sector | I15: Progress toward 2030 target | J15: 2024 change from baseline
H16: Oil & Gas | I16: ='Carbon Intensity Targets'!J5 -> 0.38222222 | J16: ='Carbon Intensity Targets'!H5 -> -0.172
H17: Electric Power | I17: ='Carbon Intensity Targets'!J6 -> 0.39855072 | J17: ='Carbon Intensity Targets'!H6 -> -0.275
H18: Auto Manufacturing | I18: ='Carbon Intensity Targets'!J7 -> 0.42291667 | J18: ='Carbon Intensity Targets'!H7 -> -0.203
H19: Iron & Steel | I19: ='Carbon Intensity Targets'!J10 -> 0.28666667 | J19: ='Carbon Intensity Targets'!H10 -> -0.086
H20: Aluminum | I20: ='Carbon Intensity Targets'!J12 -> -0.43333333 | J20: ='Carbon Intensity Targets'!H12 -> 0.104

Sheet Credit Risk Concepts
A1: Credit Risk Concepts for Climate Stress Testing
A3: Concept | B3: Formula / definition | C3: Plain-English meaning | D3: Why climate can affect it | E3: Good / bad direction | F3: Used in this model? | G3: Important caveat | H3: Source basis
A4: EAD — Exposure at Default | B4: Amount outstanding when default occurs | C4: How much the bank could be exposed to if the borrower defaults. | D4: Drawdowns or stressed liquidity needs can increase exposure. | E4: Lower is generally safer | F4: Yes | G4: Real banks model EAD by product and credit facility; our practice model uses current exposure. | H4: Credit-risk concept; public JPM data do not disclose counterparty EAD.
A5: PD — Probability of Default | B5: Probability borrower defaults over a defined horizon | C5: Chance the borrower fails to meet obligations. | D5: Lower revenue, weaker margins, higher costs and technology disruption can weaken credit quality. | E5: Lower is better | F5: Yes | G5: Our stressed PD is a training heuristic, not JPMorganChase's internal rating methodology. | H5: JPMorganChase states transition scenarios may affect client credit ratings.
A6: LGD — Loss Given Default | B6: % of EAD lost if default occurs | C6: How much the bank loses after recoveries/collateral. | D6: Physical damage, falling collateral values or weaker recovery markets can increase LGD. | E6: Lower is better | F6: Yes | G6: Our stressed LGD adjustment is illustrative. | H6: JPMorganChase discusses collateral damage and property values as credit channels.
A7: Expected Credit Loss | B7: PD × LGD × EAD | C7: Expected loss from credit risk under simplified one-period logic. | D7: Climate stress can change PD, LGD and sometimes EAD. | E7: Lower is better | F7: Yes | G7: Accounting CECL/ECL frameworks are more complex than this simple teaching equation. | H7: Training bridge from climate drivers to financial loss.
A8: EBITDA margin | B8: EBITDA ÷ Revenue | C8: Operating earnings before interest, tax, depreciation and amortization per dollar of revenue. | D8: Demand loss, pricing pressure, carbon costs and operating costs can compress margin. | E8: Higher is better | F8: Yes | G8: Sector-specific accounting and hedging can materially change outcomes. | H8: JPMorganChase cites lower revenue and higher operating costs as transition channels.
A9: Interest coverage | B9: EBITDA ÷ Interest expense | C9: How many times operating earnings cover interest. | D9: Falling EBITDA reduces debt-service cushion. | E9: Higher is better | F9: Yes | G9: Real credit analysis may use EBIT, FFO, fixed-charge coverage or other sector metrics. | H9: Training metric.
A10: Net leverage | B10: (Debt − Cash) ÷ EBITDA | C10: Debt burden relative to earnings. | D10: If EBITDA falls, leverage rises even when debt is unchanged. | E10: Lower is better | F10: Yes | G10: Oil & gas analysts may use additional reserve / production metrics. | H10: Training metric.
A11: DSCR | B11: Cash flow available for debt service ÷ Interest + scheduled principal | C11: Ability to cover required debt payments with cash flow. | D11: Transition capex and lower cash flow can reduce debt-service capacity. | E11: Higher is better | F11: Yes | G11: Our CFADS is simplified and not a bank covenant calculation. | H11: Training metric.
A13: Core mental model
A14: Climate driver → borrower revenue / costs / capex / asset value → EBITDA & cash flow → leverage / interest coverage / DSCR → credit rating or PD → expected credit loss. JPMorganChase states that for sectors more vulnerable to transition risk, including Oil & Gas, it projects detailed client cash flows within a transition scenario and estimates potential impacts on credit ratings. Our model reproduces that analytical logic at a simplified training level; it does not reproduce JPMorganChase's internal model.

Sheet O&G Scenario Inputs
A1: Oil & Gas Transition Scenario Inputs — Training Assumptions
A3: Source-derived framework: JPMorganChase uses baseline and stress climate scenarios, including NGFS-informed transition pathways, and notes that Oil & Gas client financials may be affected through weaker demand, lower revenue, carbon taxes / higher operating costs and additional capital expenditures. The numerical shocks below are illustrative training assumptions created for this exercise — they are NOT JPMorganChase or NGFS scenario values.
A7: Scenario | B7: Oil/gas price impact | C7: Demand / volume impact | D7: Additional operating cost (% revenue) | E7: Carbon price ($/tCO2e) | F7: Transition capex (% revenue) | G7: PD stress logic | H7: LGD stress logic | I7: Scenario purpose | J7: Editable?
A8: Current Policies-style | B8: 0 | C8: 0 | D8: 0 | E8: 0 | F8: 0 | G8: No incremental climate rating stress | H8: No incremental LGD stress | I8: Reference case resembling a low-transition-risk starting point. | J8: Yes
A9: Accelerated Transition | B9: -0.1 | C9: -0.05 | D9: 0.01 | E9: 75 | F9: 0.05 | G9: Credit metrics may weaken as revenue/cash flow fall | H9: Add 5 pts LGD if EBITDA falls >20% | I9: Moderate transition shock for training. | J9: Yes
A10: Severe Transition | B10: -0.25 | C10: -0.1 | D10: 0.03 | E10: 150 | F10: 0.1 | G10: Stronger rating migration if coverage/leverage deteriorate | H10: Add 10 pts LGD if EBITDA falls >35% | I10: Severe transition stress for training, directionally inspired by rapid-transition logic. | J10: Yes
A12: Borrower baseline inputs — illustrative, not JPMorganChase client data
A13: Borrower | B13: Business type | C13: Revenue ($mm) | D13: EBITDA ($mm) | E13: Debt ($mm) | F13: Cash ($mm) | G13: Interest expense ($mm) | H13: Maintenance capex ($mm) | I13: Scheduled principal ($mm) | J13: Direct emissions intensity (tCO2e / $1mm revenue) | K13: JPM exposure / EAD ($mm) | L13: Baseline PD | M13: Baseline LGD | N13: Source / status
A14: UpstreamCo | B14: Exploration & Production | C14: 5000 | D14: 1750 | E14: 3000 | F14: 400 | G14: 180 | H14: 650 | I14: 300 | J14: 150 | K14: 500 | L14: 0.015 | M14: 0.45 | N14: Synthetic training borrower
A15: IntegratedCo | B15: Integrated Oil & Gas | C15: 12000 | D15: 3000 | E15: 5500 | F15: 900 | G15: 330 | H15: 1000 | I15: 450 | J15: 90 | K15: 800 | L15: 0.01 | M15: 0.4 | N15: Synthetic training borrower
A16: ServicesCo | B16: Oilfield Services | C16: 3500 | D16: 700 | E16: 1800 | F16: 250 | G16: 140 | H16: 220 | I16: 180 | J16: 35 | K16: 300 | L16: 0.025 | M16: 0.5 | N16: Synthetic training borrower
A18: Additional model assumptions
A19: Assumption | B19: Value | C19: Unit | D19: Comment
A20: Cash tax rate on EBITDA | B20: 0.15 | C20: % | D20: Simplified training assumption.
A21: PD cap | B21: 0.2 | C21: % | D21: Prevents heuristic PD from exceeding 20% in this exercise.
A22: LGD cap | B22: 0.8 | C22: % | D22: Simplified cap for stressed LGD.

Sheet O&G Borrower Stress Test
A1: Oil & Gas Borrower Transition Stress Test
A3: Training objective: translate transition scenario drivers into borrower financial metrics and a simplified credit-loss signal. Green text = links to other workbook sheets; black = formulas. This is not an internal JPMorganChase credit model.
A6: Borrower | B6: Scenario | C6: Revenue ($mm) | D6: EBITDA ($mm) | E6: EBITDA margin | F6: Carbon cost ($mm) | G6: Transition capex ($mm) | H6: CFADS ($mm) | I6: Debt service ($mm) | J6: DSCR | K6: Interest coverage | L6: Net leverage | M6: EBITDA change | N6: Credit stress multiplier | O6: Stressed PD | P6: Stressed LGD | Q6: EAD ($mm) | R6: Expected credit loss ($mm) | S6: ECL / EAD | T6: Credit flag | U6: Key transmission channel | V6: Model status
A7: ='O&G Scenario Inputs'!A14 -> UpstreamCo | B7: ='O&G Scenario Inputs'!A8 -> Current Policies-style | C7: ='O&G Scenario Inputs'!C14*(1+'O&G Scenario Inputs'!B8)*(1+'O&G Scenario Inputs'!C8) -> 5000 | D7: =C7*('O&G Scenario Inputs'!D14/'O&G Scenario Inputs'!C14)-C7*'O&G Scenario Inputs'!D8-F7 -> 1750 | E7: =D7/C7 -> 0.35 | F7: =C7*'O&G Scenario Inputs'!J14*'O&G Scenario Inputs'!E8/1000000 -> 0 | G7: =C7*'O&G Scenario Inputs'!F8 -> 0 | H7: =D7-(MAX(D7,0)*'O&G Scenario Inputs'!B20)-'O&G Scenario Inputs'!H14-G7 -> 837.5 | I7: ='O&G Scenario Inputs'!G14+'O&G Scenario Inputs'!I14 -> 480 | J7: =H7/I7 -> 1.7447917 | K7: =D7/'O&G Scenario Inputs'!G14 -> 9.7222222 | L7: =('O&G Scenario Inputs'!E14-'O&G Scenario Inputs'!F14)/D7 -> 1.4857143 | M7: =D7/'O&G Scenario Inputs'!D14-1 -> 0 | N7: =IF(B7="Current Policies-style",1,IF(AND(K7>=4,L7<=2.5,J7>=1.5),1,IF(AND(K7>=2.5,L7<=3.5,J7>=1.2),1.5,IF(AND(K7>=1.5,J7>=1),2.5,5)))) -> 1 | O7: =MIN('O&G Scenario Inputs'!B21,'O&G Scenario Inputs'!L14*N7) -> 0.015 | P7: =MIN('O&G Scenario Inputs'!B22,'O&G Scenario Inputs'!M14+IF(M7<-0.35,0.1,IF(M7<-0.2,0.05,0))) -> 0.45 | Q7: ='O&G Scenario Inputs'!K14 -> 500 | R7: =O7*P7*Q7 -> 3.375 | S7: =R7/Q7 -> 0.00675 | T7: =IF(B7="Current Policies-style","Reference",IF(OR(J7<1,K7<1.5),"Severe",IF(OR(J7<1.2,K7<2.5),"Watch","Stable"))) -> Reference | U7: =IF(B7="Current Policies-style","Reference case",IF(F7>1,"Revenue + carbon cost + transition capex","Revenue pressure + transition capex")) -> Reference case | V7: Illustrative training model
A8: ='O&G Scenario Inputs'!A14 -> UpstreamCo | B8: ='O&G Scenario Inputs'!A9 -> Accelerated Transition | C8: ='O&G Scenario Inputs'!C14*(1+'O&G Scenario Inputs'!B9)*(1+'O&G Scenario Inputs'!C9) -> 4275 | D8: =C8*('O&G Scenario Inputs'!D14/'O&G Scenario Inputs'!C14)-C8*'O&G Scenario Inputs'!D9-F8 -> 1405.4062 | E8: =D8/C8 -> 0.32875 | F8: =C8*'O&G Scenario Inputs'!J14*'O&G Scenario Inputs'!E9/1000000 -> 48.09375 | G8: =C8*'O&G Scenario Inputs'!F9 -> 213.75 | H8: =D8-(MAX(D8,0)*'O&G Scenario Inputs'!B20)-'O&G Scenario Inputs'!H14-G8 -> 330.84531 | I8: ='O&G Scenario Inputs'!G14+'O&G Scenario Inputs'!I14 -> 480 | J8: =H8/I8 -> 0.68926107 | K8: =D8/'O&G Scenario Inputs'!G14 -> 7.8078125 | L8: =('O&G Scenario Inputs'!E14-'O&G Scenario Inputs'!F14)/D8 -> 1.8499989 | M8: =D8/'O&G Scenario Inputs'!D14-1 -> -0.19691071 | N8: =IF(B8="Current Policies-style",1,IF(AND(K8>=4,L8<=2.5,J8>=1.5),1,IF(AND(K8>=2.5,L8<=3.5,J8>=1.2),1.5,IF(AND(K8>=1.5,J8>=1),2.5,5)))) -> 5 | O8: =MIN('O&G Scenario Inputs'!B21,'O&G Scenario Inputs'!L14*N8) -> 0.075 | P8: =MIN('O&G Scenario Inputs'!B22,'O&G Scenario Inputs'!M14+IF(M8<-0.35,0.1,IF(M8<-0.2,0.05,0))) -> 0.45 | Q8: ='O&G Scenario Inputs'!K14 -> 500 | R8: =O8*P8*Q8 -> 16.875 | S8: =R8/Q8 -> 0.03375 | T8: =IF(B8="Current Policies-style","Reference",IF(OR(J8<1,K8<1.5),"Severe",IF(OR(J8<1.2,K8<2.5),"Watch","Stable"))) -> Severe | U8: =IF(B8="Current Policies-style","Reference case",IF(F8>1,"Revenue + carbon cost + transition capex","Revenue pressure + transition capex")) -> Revenue + carbon cost + transition capex | V8: Illustrative training model
A9: ='O&G Scenario Inputs'!A14 -> UpstreamCo | B9: ='O&G Scenario Inputs'!A10 -> Severe Transition | C9: ='O&G Scenario Inputs'!C14*(1+'O&G Scenario Inputs'!B10)*(1+'O&G Scenario Inputs'!C10) -> 3375 | D9: =C9*('O&G Scenario Inputs'!D14/'O&G Scenario Inputs'!C14)-C9*'O&G Scenario Inputs'!D10-F9 -> 1004.0625 | E9: =D9/C9 -> 0.2975 | F9: =C9*'O&G Scenario Inputs'!J14*'O&G Scenario Inputs'!E10/1000000 -> 75.9375 | G9: =C9*'O&G Scenario Inputs'!F10 -> 337.5 | H9: =D9-(MAX(D9,0)*'O&G Scenario Inputs'!B20)-'O&G Scenario Inputs'!H14-G9 -> -134.04688 | I9: ='O&G Scenario Inputs'!G14+'O&G Scenario Inputs'!I14 -> 480 | J9: =H9/I9 -> -0.27926432 | K9: =D9/'O&G Scenario Inputs'!G14 -> 5.578125 | L9: =('O&G Scenario Inputs'!E14-'O&G Scenario Inputs'!F14)/D9 -> 2.5894802 | M9: =D9/'O&G Scenario Inputs'!D14-1 -> -0.42625 | N9: =IF(B9="Current Policies-style",1,IF(AND(K9>=4,L9<=2.5,J9>=1.5),1,IF(AND(K9>=2.5,L9<=3.5,J9>=1.2),1.5,IF(AND(K9>=1.5,J9>=1),2.5,5)))) -> 5 | O9: =MIN('O&G Scenario Inputs'!B21,'O&G Scenario Inputs'!L14*N9) -> 0.075 | P9: =MIN('O&G Scenario Inputs'!B22,'O&G Scenario Inputs'!M14+IF(M9<-0.35,0.1,IF(M9<-0.2,0.05,0))) -> 0.55 | Q9: ='O&G Scenario Inputs'!K14 -> 500 | R9: =O9*P9*Q9 -> 20.625 | S9: =R9/Q9 -> 0.04125 | T9: =IF(B9="Current Policies-style","Reference",IF(OR(J9<1,K9<1.5),"Severe",IF(OR(J9<1.2,K9<2.5),"Watch","Stable"))) -> Severe | U9: =IF(B9="Current Policies-style","Reference case",IF(F9>1,"Revenue + carbon cost + transition capex","Revenue pressure + transition capex")) -> Revenue + carbon cost + transition capex | V9: Illustrative training model
A10: ='O&G Scenario Inputs'!A15 -> IntegratedCo | B10: ='O&G Scenario Inputs'!A8 -> Current Policies-style | C10: ='O&G Scenario Inputs'!C15*(1+'O&G Scenario Inputs'!B8)*(1+'O&G Scenario Inputs'!C8) -> 12000 | D10: =C10*('O&G Scenario Inputs'!D15/'O&G Scenario Inputs'!C15)-C10*'O&G Scenario Inputs'!D8-F10 -> 3000 | E10: =D10/C10 -> 0.25 | F10: =C10*'O&G Scenario Inputs'!J15*'O&G Scenario Inputs'!E8/1000000 -> 0 | G10: =C10*'O&G Scenario Inputs'!F8 -> 0 | H10: =D10-(MAX(D10,0)*'O&G Scenario Inputs'!B20)-'O&G Scenario Inputs'!H15-G10 -> 1550 | I10: ='O&G Scenario Inputs'!G15+'O&G Scenario Inputs'!I15 -> 780 | J10: =H10/I10 -> 1.9871795 | K10: =D10/'O&G Scenario Inputs'!G15 -> 9.0909091 | L10: =('O&G Scenario Inputs'!E15-'O&G Scenario Inputs'!F15)/D10 -> 1.5333333 | M10: =D10/'O&G Scenario Inputs'!D15-1 -> 0 | N10: =IF(B10="Current Policies-style",1,IF(AND(K10>=4,L10<=2.5,J10>=1.5),1,IF(AND(K10>=2.5,L10<=3.5,J10>=1.2),1.5,IF(AND(K10>=1.5,J10>=1),2.5,5)))) -> 1 | O10: =MIN('O&G Scenario Inputs'!B21,'O&G Scenario Inputs'!L15*N10) -> 0.01 | P10: =MIN('O&G Scenario Inputs'!B22,'O&G Scenario Inputs'!M15+IF(M10<-0.35,0.1,IF(M10<-0.2,0.05,0))) -> 0.4 | Q10: ='O&G Scenario Inputs'!K15 -> 800 | R10: =O10*P10*Q10 -> 3.2 | S10: =R10/Q10 -> 0.004 | T10: =IF(B10="Current Policies-style","Reference",IF(OR(J10<1,K10<1.5),"Severe",IF(OR(J10<1.2,K10<2.5),"Watch","Stable"))) -> Reference | U10: =IF(B10="Current Policies-style","Reference case",IF(F10>1,"Revenue + carbon cost + transition capex","Revenue pressure + transition capex")) -> Reference case | V10: Illustrative training model
A11: ='O&G Scenario Inputs'!A15 -> IntegratedCo | B11: ='O&G Scenario Inputs'!A9 -> Accelerated Transition | C11: ='O&G Scenario Inputs'!C15*(1+'O&G Scenario Inputs'!B9)*(1+'O&G Scenario Inputs'!C9) -> 10260 | D11: =C11*('O&G Scenario Inputs'!D15/'O&G Scenario Inputs'!C15)-C11*'O&G Scenario Inputs'!D9-F11 -> 2393.145 | E11: =D11/C11 -> 0.23325 | F11: =C11*'O&G Scenario Inputs'!J15*'O&G Scenario Inputs'!E9/1000000 -> 69.255 | G11: =C11*'O&G Scenario Inputs'!F9 -> 513 | H11: =D11-(MAX(D11,0)*'O&G Scenario Inputs'!B20)-'O&G Scenario Inputs'!H15-G11 -> 521.17325 | I11: ='O&G Scenario Inputs'!G15+'O&G Scenario Inputs'!I15 -> 780 | J11: =H11/I11 -> 0.66817083 | K11: =D11/'O&G Scenario Inputs'!G15 -> 7.2519545 | L11: =('O&G Scenario Inputs'!E15-'O&G Scenario Inputs'!F15)/D11 -> 1.9221568 | M11: =D11/'O&G Scenario Inputs'!D15-1 -> -0.202285 | N11: =IF(B11="Current Policies-style",1,IF(AND(K11>=4,L11<=2.5,J11>=1.5),1,IF(AND(K11>=2.5,L11<=3.5,J11>=1.2),1.5,IF(AND(K11>=1.5,J11>=1),2.5,5)))) -> 5 | O11: =MIN('O&G Scenario Inputs'!B21,'O&G Scenario Inputs'!L15*N11) -> 0.05 | P11: =MIN('O&G Scenario Inputs'!B22,'O&G Scenario Inputs'!M15+IF(M11<-0.35,0.1,IF(M11<-0.2,0.05,0))) -> 0.45 | Q11: ='O&G Scenario Inputs'!K15 -> 800 | R11: =O11*P11*Q11 -> 18 | S11: =R11/Q11 -> 0.0225 | T11: =IF(B11="Current Policies-style","Reference",IF(OR(J11<1,K11<1.5),"Severe",IF(OR(J11<1.2,K11<2.5),"Watch","Stable"))) -> Severe | U11: =IF(B11="Current Policies-style","Reference case",IF(F11>1,"Revenue + carbon cost + transition capex","Revenue pressure + transition capex")) -> Revenue + carbon cost + transition capex | V11: Illustrative training model
A12: ='O&G Scenario Inputs'!A15 -> IntegratedCo | B12: ='O&G Scenario Inputs'!A10 -> Severe Transition | C12: ='O&G Scenario Inputs'!C15*(1+'O&G Scenario Inputs'!B10)*(1+'O&G Scenario Inputs'!C10) -> 8100 | D12: =C12*('O&G Scenario Inputs'!D15/'O&G Scenario Inputs'!C15)-C12*'O&G Scenario Inputs'!D10-F12 -> 1672.65 | E12: =D12/C12 -> 0.2065 | F12: =C12*'O&G Scenario Inputs'!J15*'O&G Scenario Inputs'!E10/1000000 -> 109.35 | G12: =C12*'O&G Scenario Inputs'!F10 -> 810 | H12: =D12-(MAX(D12,0)*'O&G Scenario Inputs'!B20)-'O&G Scenario Inputs'!H15-G12 -> -388.2475 | I12: ='O&G Scenario Inputs'!G15+'O&G Scenario Inputs'!I15 -> 780 | J12: =H12/I12 -> -0.49775321 | K12: =D12/'O&G Scenario Inputs'!G15 -> 5.0686364 | L12: =('O&G Scenario Inputs'!E15-'O&G Scenario Inputs'!F15)/D12 -> 2.750127 | M12: =D12/'O&G Scenario Inputs'!D15-1 -> -0.44245 | N12: =IF(B12="Current Policies-style",1,IF(AND(K12>=4,L12<=2.5,J12>=1.5),1,IF(AND(K12>=2.5,L12<=3.5,J12>=1.2),1.5,IF(AND(K12>=1.5,J12>=1),2.5,5)))) -> 5 | O12: =MIN('O&G Scenario Inputs'!B21,'O&G Scenario Inputs'!L15*N12) -> 0.05 | P12: =MIN('O&G Scenario Inputs'!B22,'O&G Scenario Inputs'!M15+IF(M12<-0.35,0.1,IF(M12<-0.2,0.05,0))) -> 0.5 | Q12: ='O&G Scenario Inputs'!K15 -> 800 | R12: =O12*P12*Q12 -> 20 | S12: =R12/Q12 -> 0.025 | T12: =IF(B12="Current Policies-style","Reference",IF(OR(J12<1,K12<1.5),"Severe",IF(OR(J12<1.2,K12<2.5),"Watch","Stable"))) -> Severe | U12: =IF(B12="Current Policies-style","Reference case",IF(F12>1,"Revenue + carbon cost + transition capex","Revenue pressure + transition capex")) -> Revenue + carbon cost + transition capex | V12: Illustrative training model
A13: ='O&G Scenario Inputs'!A16 -> ServicesCo | B13: ='O&G Scenario Inputs'!A8 -> Current Policies-style | C13: ='O&G Scenario Inputs'!C16*(1+'O&G Scenario Inputs'!B8)*(1+'O&G Scenario Inputs'!C8) -> 3500 | D13: =C13*('O&G Scenario Inputs'!D16/'O&G Scenario Inputs'!C16)-C13*'O&G Scenario Inputs'!D8-F13 -> 700 | E13: =D13/C13 -> 0.2 | F13: =C13*'O&G Scenario Inputs'!J16*'O&G Scenario Inputs'!E8/1000000 -> 0 | G13: =C13*'O&G Scenario Inputs'!F8 -> 0 | H13: =D13-(MAX(D13,0)*'O&G Scenario Inputs'!B20)-'O&G Scenario Inputs'!H16-G13 -> 375 | I13: ='O&G Scenario Inputs'!G16+'O&G Scenario Inputs'!I16 -> 320 | J13: =H13/I13 -> 1.171875 | K13: =D13/'O&G Scenario Inputs'!G16 -> 5 | L13: =('O&G Scenario Inputs'!E16-'O&G Scenario Inputs'!F16)/D13 -> 2.2142857 | M13: =D13/'O&G Scenario Inputs'!D16-1 -> 0 | N13: =IF(B13="Current Policies-style",1,IF(AND(K13>=4,L13<=2.5,J13>=1.5),1,IF(AND(K13>=2.5,L13<=3.5,J13>=1.2),1.5,IF(AND(K13>=1.5,J13>=1),2.5,5)))) -> 1 | O13: =MIN('O&G Scenario Inputs'!B21,'O&G Scenario Inputs'!L16*N13) -> 0.025 | P13: =MIN('O&G Scenario Inputs'!B22,'O&G Scenario Inputs'!M16+IF(M13<-0.35,0.1,IF(M13<-0.2,0.05,0))) -> 0.5 | Q13: ='O&G Scenario Inputs'!K16 -> 300 | R13: =O13*P13*Q13 -> 3.75 | S13: =R13/Q13 -> 0.0125 | T13: =IF(B13="Current Policies-style","Reference",IF(OR(J13<1,K13<1.5),"Severe",IF(OR(J13<1.2,K13<2.5),"Watch","Stable"))) -> Reference | U13: =IF(B13="Current Policies-style","Reference case",IF(F13>1,"Revenue + carbon cost + transition capex","Revenue pressure + transition capex")) -> Reference case | V13: Illustrative training model
A14: ='O&G Scenario Inputs'!A16 -> ServicesCo | B14: ='O&G Scenario Inputs'!A9 -> Accelerated Transition | C14: ='O&G Scenario Inputs'!C16*(1+'O&G Scenario Inputs'!B9)*(1+'O&G Scenario Inputs'!C9) -> 2992.5 | D14: =C14*('O&G Scenario Inputs'!D16/'O&G Scenario Inputs'!C16)-C14*'O&G Scenario Inputs'!D9-F14 -> 560.71969 | E14: =D14/C14 -> 0.187375 | F14: =C14*'O&G Scenario Inputs'!J16*'O&G Scenario Inputs'!E9/1000000 -> 7.8553125 | G14: =C14*'O&G Scenario Inputs'!F9 -> 149.625 | H14: =D14-(MAX(D14,0)*'O&G Scenario Inputs'!B20)-'O&G Scenario Inputs'!H16-G14 -> 106.98673 | I14: ='O&G Scenario Inputs'!G16+'O&G Scenario Inputs'!I16 -> 320 | J14: =H14/I14 -> 0.33433354 | K14: =D14/'O&G Scenario Inputs'!G16 -> 4.0051406 | L14: =('O&G Scenario Inputs'!E16-'O&G Scenario Inputs'!F16)/D14 -> 2.7643046 | M14: =D14/'O&G Scenario Inputs'!D16-1 -> -0.19897187 | N14: =IF(B14="Current Policies-style",1,IF(AND(K14>=4,L14<=2.5,J14>=1.5),1,IF(AND(K14>=2.5,L14<=3.5,J14>=1.2),1.5,IF(AND(K14>=1.5,J14>=1),2.5,5)))) -> 5 | O14: =MIN('O&G Scenario Inputs'!B21,'O&G Scenario Inputs'!L16*N14) -> 0.125 | P14: =MIN('O&G Scenario Inputs'!B22,'O&G Scenario Inputs'!M16+IF(M14<-0.35,0.1,IF(M14<-0.2,0.05,0))) -> 0.5 | Q14: ='O&G Scenario Inputs'!K16 -> 300 | R14: =O14*P14*Q14 -> 18.75 | S14: =R14/Q14 -> 0.0625 | T14: =IF(B14="Current Policies-style","Reference",IF(OR(J14<1,K14<1.5),"Severe",IF(OR(J14<1.2,K14<2.5),"Watch","Stable"))) -> Severe | U14: =IF(B14="Current Policies-style","Reference case",IF(F14>1,"Revenue + carbon cost + transition capex","Revenue pressure + transition capex")) -> Revenue + carbon cost + transition capex | V14: Illustrative training model
